Workbook

Sheet Fiche d'embauche (2)
B2: FICHE DE VALIDATION D'EMBAUCHE
A4: =TODAY()
A7: Direction Demandeuse | C7: Direction RH | H7: Direction Générale
A8: {directionDemandeuseName} | C8: {directionRHName} | G8: {directionGeneraleName}
A13: Fonction
A14: Titre de poste: | C14: {titrePoste}
A16: Direction/ Département: | C16: {directionDepartement}
A18: Rattachement Hiérarchique: | C18: {rattachementHierarchique}
A20: Motif de recrutement: | C20: {motifRecrutement}
K21: Cadre : | M21: 91 | N21: Dh/jour fixe | O21: {ikCadreSelected} | P21: =M21*O21
A22: Nom & Prénom du candidat retenu | D22: {nomPrenom} | K22: Chef de département : | M22: 127 | N22: Dh/jour fixe | O22: {ikChefSelected} | P22: =M22*O22
A25: REÇU EN ENTRETIEN PAR : | K25: Ait Baha : | M25: 130 | N25: kms | O25: {ikAitBahaSelected} | P25: =M25*O25
B26: {interviewer1Name} | E26: {interviewer1Avis} | K26: Marrakech : | M26: 110 | N26: kms | O26: {ikMarrakechSelected} | P26: =M26*O26
B27: {interviewer2Name} | E27: {interviewer2Avis} | K27: Safi : | M27: 70 | N27: kms | O27: {ikSafiSelected} | P27: =M27*O27
B28: {interviewer3Name} | E28: {interviewer3Avis} | K28: Laâyoune | M28: 72 | N28: kms | O28: {ikLaayouneSelected} | P28: =M28*O28
B29: {interviewer4Name} | E29: {interviewer4Avis} | K29: Jorf Lasfar : | M29: 64 | N29: kms | O29: {ikJorfSelected} | P29: =M29*O29
K30: Casablanca : | M30: 50 | N30: kms | O30: {ikCasablancaSelected} | P30: =M30*O30
A32: Entrée en fonction: | K32: Nombre de jours travaillés | M32: {nombreJoursTravailles} | N32: jours | O32: =22*(O21*P21+O22*P22+2*(P25+P26+P27+P28+P29+P30)) | P32: Dhs
B33: Durée de préavis: | E33: {dureePreavis}
B34: Entrée envisagé le: | E34: {entreeEnvisagee}
B35: Statut: | E35: {statut}
B36: Type de contrat: | E36: {typeContrat}
B37: Durée de période d'essai | E37: {dureePeriodeEssai}
B38: Voiture liée au poste: | E38: {voitureLieePoste} | Q38: =D22
A40: Situation Actuelle | F40: Offre Ciments du Maroc
F41: Salaire de base | H41: {salaireBase} | I41: Dhs brut sur 13,3 mois | K41: Salaire annuel brut : | M41: =H41*13.3+(H42+H43+H44)*12+H45 | N41: Dhs | Q41: Salaire de base | S41: =H41 | T41: Dhs brut sur 12 mois
A42: Salaire de base: | C42: {salaireBaseActuel} | F42: Prime de logement | H42: {primeLogement} | I42: Dhs brut sur 12 mois | K42: MBO | M42: =H41 | N42: Dhs | Q42: Prime de logement | S42: =H42 | T42: Dhs brut sur 12 mois
A43: Prime de chantier | C43: {primeChantierActuel} | F43: Prime de site | H43: {primeSite} | I43: Dhs brut sur 12 mois | Q43: Prime de site | S43: =H43 | T43: Dhs brut sur 12 mois
A44: Indemnité de panier | C44: {indPanierActuel} | F44: Indemnité de transport | H44: {indTransport} | I44: Dhs net sur 12 mois | K44: Net mensuel | M44: ='Simulateur Mensuel'!D49 | N44: Dhs
A45: Indemnité de transport | C45: {indTransportActuel} | F45: Prime de représentation | H45: {primeRepresentation} | I45: Dhs brut sur 12 mois | K45: Net mensuel + IK | M45: =M44+O32 | N45: Dhs
A46: Salaire Net: | C46: {salaireNetActuel}
F47: Salaire net mensuel | H47: =M44
F48: IK | H48: =+O32 | K48: Net annuel sur 12 mois | M48: =(M44*12+H41*1.3*0.62)/12 | N48: Dhs | Q48: Net mensuel | S48: =M44 | T48: Dhs
F49: Salaire net perçu | H49: =H47+H48 | K49: IK sur 12 mois | M49: =O32*11/12 | N49: Dhs
H50: =(H49-C46)/C46 | K50: Moyen net sur 12 mois | M50: =M48+M49 | N50: Dhs | Q50: Indemnités Kil: | S50: =O32
A51: Comparatif Interne
Q52: Bonus (MBO) | S52: =H41 | T52: Dhs bruts pour 100%
A54: Nom et prénom | B54: Intitulé du poste | C54: Site d'affe- ctation | D54: Salaire Brut | E54: Prime de logement | F54: Prime de site | G54: Prime de représentation | H54: Ancienneté CIMAR | I54: Nombre d'expérience avant intégration CIMAR | Q54: CIMR | T54: {tauxCIMR}
Q55: Mutuelle maladie WafaAssurances | T55: {mutuellePercent}
Q56: Prime de l'aïd | T56: {primeAid} | U56: Dhs bruts
...

Sheet Simulateur Mensuel
B6: Barèmre IGR 2010
B7: Tranche | C7: Taux | D7: Somme à déduire
B8: [0-3333] | C8: 0 | D8: 0
B9: [3334-5000] | C9: 0.1 | D9: 333.33
B10: [5001-6667] | C10: 0.2 | D10: 833.33
B11: [6668-8333] | C11: 0.3 | D11: 1500
B12: [8334-15000] | C12: 0.34 | D12: 1833.33
B13: 15001 et plus | C13: 0.37 | D13: 2283.33
B15: Taux appliqués
B16: Rubriques | C16: Taux | D16: Plafond
B17: Frais professionnels | C17: =IF(E34<=6500,35%,25%) | D17: =35000/12
B18: CNSS | C18: =4.29%+0.19% | D18: 6000
B19: CIMR (3%,3,75%,4,5%,5,25% ou 6%) | C19: {tauxCIMRDecimal} | D19: 2000000
B20: Retraite Complémentaire | C20: 0 | D20: N/A
B21: Retraite 55 ans | C21: 0
B22: Mutuelle | C22: 0.0341 | D22: N/A
B23: Charges familliales | C23: 41.66 | D23: 3
B26: Nombre de personnes à charge | E26: {nbPersonnesCharge}
B27: Salaire brut de base | E27: =+'Fiche d''embauche (2)'!H41
B28: Taux Ancienneté | E28: {tauxAnciennete}
B29: Prime de représentation | E29: ='Fiche d''embauche (2)'!H45
B30: Indemnite imposable | E30: =+'Fiche d''embauche (2)'!H42+'Fiche d''embauche (2)'!H43
B31: Rma | E31: {rma}
B32: Salaire brut imposable | E32: =E27+E29+E30
B33: Indem Transport | E33: =+'Fiche d''embauche (2)'!H44
B34: Revenu brut global | E34: =E27+E29+E30
B35: Interets prêt immobilier | E35: {interetsPretImmobilier}
B36: Montant du revenu brut imposable | E36: =+E27+E29+E30+E31
B38: Frais professionnels | D38: =IF((E36*C17)<=D17,(E36*C17),D17)
B39: CNSS | D39: =IF((E36<=D18),(E36*C18),(D18*C18))
B40: CIMR | D40: =IF((E36<=D19),(E36*C19),(D19*C19))
B41: Retraite Complémentaire | D41: 0
B42: Retraite 55 ans | D42: 0
B43: Mutuelle | D43: =E36*C22
B44: Salaire Brut Imposable | D44: =E36-D38-D39-D40-D41-D42-D43-E35
B45: IGR Brut | D45: =IF(D44<=3333.33,(D44*C8)-D8,IF(D44<=5000,(D44*C9)-D9,IF(D44<=6667,(D44*C10)-D10,IF(D44<=8333.33,(D44*C11)-D11,IF(D44<=15000,(D44*C12)-D12,IF(D44>=15001,(D44*C13)-D13))))))
B46: Charges familliales | D46: =IF((E26)<=6,(E26*C23),(D23))
B47: CSS | D47: 0
B48: IGR NET | D48: =+D45-D46
B49: Net à payer | D49: =E27+E29+E30-D39-D40-D43-D48+E33
...

Sheet Feuil2
E4: VALIDATION EMBAUCHE | J4: X | K4: CADRE
A5: DATE : | B5: =TODAY()
E6: Création | G6: x | H6: remplacement | K6: Mensuel
A9: Age : 31 ans
C11: DIRECTION DEMANDEUR | F11: DRH | I11: DG
A12: Nom : | C12: Nom : | D12: M. TERES | F12: Nom : | G12: M. EL GHAZI | I12: Nom : M. ROZZANIGO
A17: Visa : | C17: Visa : | F17: Visa : | I17: Visa :
A19: FONCTION
B20: TITRE DU POSTE : | E20: Acheteur Senior
B22: UNITE / SERVICE : | E22: Direction des Achats
B24: NOM & PRENOM : | E24: M. Kamal HARGUIL
C26: REÇU EN ENTRETIEN PAR :
B28: M. TERES | E28: Avis favorable
B29: M. EL GHAZI | E29: Avis favorable
B30: M Brahim BASAID | E30: Avis favorable
B31: M. Jillali NEMMASSI | E31: Avis favorable
B32: Mme Ghita KBILA | E32: Avis favorable
A34: ENTRÉE EN FONCTION
B35: DURÉE DU PRÉAVIS | E35: 1 mois
B36: ENTRÉE ENVISAGÉE LE | E36: 44896
A38: RÉMUNÉRATION
B39: SALAIRE | E39: Salaire de base | H39: 14200 | I39: Dhs brut sur 13,3 mois
E40: Prime de logement | H40: 3000 | I40: Dhs brut sur 12 mois
B45: STATUT | E45: Cadre
B46: DURÉE PÉRIODE D'ESSAI | E46: 3 mois renouvellable une fois
A48: TYPE DE CONTRAT
E49: CONTRAT A DURÉE INDÉTERMINÉE
A51: INFORMATIONS CONCERNANT L'EMBAUCHE
B53: Formation initiale : | C53: 2010 | D53: Bac. Scientifique - Lycée Chawki
C54: 2016 | D54: Master en Management International et Logistique - HEM Casablanca
D55: Master en Affaires Internationales - IAE Lyon
B58: Nb d'années d'exp : | C58: 5 ans | D58: Acheteur dans plusieurs secteurs
B62: Remarques diverses : | C62: Voir CV
